Traceback (most recent call last):
  File "/opt/hostedtoolcache/Python/3.8.18/x64/lib/python3.8/site-packages/jupyter_core/utils/__init__.py", line 154, in wrapped
    asyncio.get_running_loop()
RuntimeError: no running event loop

During handling of the above exception, another exception occurred:

Traceback (most recent call last):
  File "/opt/hostedtoolcache/Python/3.8.18/x64/lib/python3.8/site-packages/jupyter_cache/executors/utils.py", line 58, in single_nb_execution
    executenb(
  File "/opt/hostedtoolcache/Python/3.8.18/x64/lib/python3.8/site-packages/nbclient/client.py", line 1305, in execute
    return NotebookClient(nb=nb, resources=resources, km=km, **kwargs).execute()
  File "/opt/hostedtoolcache/Python/3.8.18/x64/lib/python3.8/site-packages/jupyter_core/utils/__init__.py", line 158, in wrapped
    return loop.run_until_complete(inner)
  File "/opt/hostedtoolcache/Python/3.8.18/x64/lib/python3.8/asyncio/base_events.py", line 616, in run_until_complete
    return future.result()
  File "/opt/hostedtoolcache/Python/3.8.18/x64/lib/python3.8/site-packages/nbclient/client.py", line 705, in async_execute
    await self.async_execute_cell(
  File "/opt/hostedtoolcache/Python/3.8.18/x64/lib/python3.8/site-packages/nbclient/client.py", line 1058, in async_execute_cell
    await self._check_raise_for_error(cell, cell_index, exec_reply)
  File "/opt/hostedtoolcache/Python/3.8.18/x64/lib/python3.8/site-packages/nbclient/client.py", line 914, in _check_raise_for_error
    raise CellExecutionError.from_cell_and_msg(cell, exec_reply_content)
nbclient.exceptions.CellExecutionError: An error occurred while executing the following cell:
------------------
# add an empty dimension
y = np.arange(3)

print(y.shape)

z = [y: np.newaxis]

print(z.shape)
print(z)
------------------


[0;36m  Cell [0;32mIn[43], line 6[0;36m[0m
[0;31m    z = [y: np.newaxis][0m
[0m          ^[0m
[0;31mSyntaxError[0m[0;31m:[0m invalid syntax


