Traceback (most recent call last):
  File "/opt/hostedtoolcache/Python/3.8.18/x64/lib/python3.8/site-packages/jupyter_core/utils/__init__.py", line 154, in wrapped
    asyncio.get_running_loop()
RuntimeError: no running event loop

During handling of the above exception, another exception occurred:

Traceback (most recent call last):
  File "/opt/hostedtoolcache/Python/3.8.18/x64/lib/python3.8/site-packages/jupyter_cache/executors/utils.py", line 58, in single_nb_execution
    executenb(
  File "/opt/hostedtoolcache/Python/3.8.18/x64/lib/python3.8/site-packages/nbclient/client.py", line 1305, in execute
    return NotebookClient(nb=nb, resources=resources, km=km, **kwargs).execute()
  File "/opt/hostedtoolcache/Python/3.8.18/x64/lib/python3.8/site-packages/jupyter_core/utils/__init__.py", line 158, in wrapped
    return loop.run_until_complete(inner)
  File "/opt/hostedtoolcache/Python/3.8.18/x64/lib/python3.8/asyncio/base_events.py", line 616, in run_until_complete
    return future.result()
  File "/opt/hostedtoolcache/Python/3.8.18/x64/lib/python3.8/site-packages/nbclient/client.py", line 705, in async_execute
    await self.async_execute_cell(
  File "/opt/hostedtoolcache/Python/3.8.18/x64/lib/python3.8/site-packages/nbclient/client.py", line 1058, in async_execute_cell
    await self._check_raise_for_error(cell, cell_index, exec_reply)
  File "/opt/hostedtoolcache/Python/3.8.18/x64/lib/python3.8/site-packages/nbclient/client.py", line 914, in _check_raise_for_error
    raise CellExecutionError.from_cell_and_msg(cell, exec_reply_content)
nbclient.exceptions.CellExecutionError: An error occurred while executing the following cell:
------------------
# Rydberg constant in spec units

R_H_cm = Rydberg * 1e-2 # cm^-1

# Print to check
print("e =", e, "C")
print("h =", h, "JÂ·s")
print("c =", c, "m/s")
print("Îµ0 =", epsilon0, "F/m")
print("m_e =", m_e, "kg")
print("R_H =", R_H_cm, "cm^-1")

------------------

----- stdout -----
e = 1.602176634e-19 C
h = 6.62607015e-34 JÂ·s
c = 299792458.0 m/s
------------------

[0;31m---------------------------------------------------------------------------[0m
[0;31mNameError[0m                                 Traceback (most recent call last)
Cell [0;32mIn[2], line 9[0m
[1;32m      7[0m [38;5;28mprint[39m([38;5;124m"[39m[38;5;124mh =[39m[38;5;124m"[39m, h, [38;5;124m"[39m[38;5;124mJÂ·s[39m[38;5;124m"[39m)
[1;32m      8[0m [38;5;28mprint[39m([38;5;124m"[39m[38;5;124mc =[39m[38;5;124m"[39m, c, [38;5;124m"[39m[38;5;124mm/s[39m[38;5;124m"[39m)
[0;32m----> 9[0m [38;5;28mprint[39m([38;5;124m"[39m[38;5;124mÎµ0 =[39m[38;5;124m"[39m, [43mepsilon0[49m, [38;5;124m"[39m[38;5;124mF/m[39m[38;5;124m"[39m)
[1;32m     10[0m [38;5;28mprint[39m([38;5;124m"[39m[38;5;124mm_e =[39m[38;5;124m"[39m, m_e, [38;5;124m"[39m[38;5;124mkg[39m[38;5;124m"[39m)
[1;32m     11[0m [38;5;28mprint[39m([38;5;124m"[39m[38;5;124mR_H =[39m[38;5;124m"[39m, R_H_cm, [38;5;124m"[39m[38;5;124mcm^-1[39m[38;5;124m"[39m)

[0;31mNameError[0m: name 'epsilon0' is not defined

